Traceback (most recent call last):
  File "/opt/anaconda3/lib/python3.8/site-packages/jupyter_cache/executors/utils.py", line 51, in single_nb_execution
    executenb(
  File "/opt/anaconda3/lib/python3.8/site-packages/nbclient/client.py", line 1087, in execute
    return NotebookClient(nb=nb, resources=resources, km=km, **kwargs).execute()
  File "/opt/anaconda3/lib/python3.8/site-packages/nbclient/util.py", line 74, in wrapped
    return just_run(coro(*args, **kwargs))
  File "/opt/anaconda3/lib/python3.8/site-packages/nbclient/util.py", line 53, in just_run
    return loop.run_until_complete(coro)
  File "/opt/anaconda3/lib/python3.8/asyncio/base_events.py", line 616, in run_until_complete
    return future.result()
  File "/opt/anaconda3/lib/python3.8/site-packages/nbclient/client.py", line 540, in async_execute
    await self.async_execute_cell(
  File "/opt/anaconda3/lib/python3.8/site-packages/nbclient/client.py", line 832, in async_execute_cell
    self._check_raise_for_error(cell, exec_reply)
  File "/opt/anaconda3/lib/python3.8/site-packages/nbclient/client.py", line 740, in _check_raise_for_error
    raise CellExecutionError.from_cell_and_msg(cell, exec_reply['content'])
nbclient.exceptions.CellExecutionError: An error occurred while executing the following cell:
------------------
# MAP estimation
fig, ax = plt.subplots()
plot_inference(z_map, z_hist, ax, map_estimate=True)
ax.set_ylabel("MAP state")
ax.set_title("Viterbi")

------------------

[0;31m---------------------------------------------------------------------------[0m
[0;31mNameError[0m                                 Traceback (most recent call last)
[0;32m<ipython-input-12-d20416120056>[0m in [0;36m<module>[0;34m[0m
[1;32m      1[0m [0;31m# MAP estimation[0m[0;34m[0m[0;34m[0m[0;34m[0m[0m
[1;32m      2[0m [0mfig[0m[0;34m,[0m [0max[0m [0;34m=[0m [0mplt[0m[0;34m.[0m[0msubplots[0m[0;34m([0m[0;34m)[0m[0;34m[0m[0;34m[0m[0m
[0;32m----> 3[0;31m [0mplot_inference[0m[0;34m([0m[0mz_map[0m[0;34m,[0m [0mz_hist[0m[0;34m,[0m [0max[0m[0;34m,[0m [0mmap_estimate[0m[0;34m=[0m[0;32mTrue[0m[0;34m)[0m[0;34m[0m[0;34m[0m[0m
[0m[1;32m      4[0m [0max[0m[0;34m.[0m[0mset_ylabel[0m[0;34m([0m[0;34m"MAP state"[0m[0;34m)[0m[0;34m[0m[0;34m[0m[0m
[1;32m      5[0m [0max[0m[0;34m.[0m[0mset_title[0m[0;34m([0m[0;34m"Viterbi"[0m[0;34m)[0m[0;34m[0m[0;34m[0m[0m

[0;31mNameError[0m: name 'z_map' is not defined
NameError: name 'z_map' is not defined

